Workbook
Name ALL2ALL_CORE2CORE_TIME_MS: LAMBDA(global_data_traffic_in_mib, global_data_traffic_in_mib * 1024^2 /(2 * HW_SPEC("Core-to-Core ICI Bandwidth (uni, GB/s)") *1024^3)*1000)
Name ALL2ALL_CHIP2CHIP_TIME_MS: LAMBDA(data_size_in_mib, bisection_links, data_size_in_mib * 1024^2 /4 / (bisection_links * HW_SPEC("Chip-to-Chip ICI Bandwidth (uni, GB/s)") *1000^3) *1000)
Name EXTRACT_ACTIVATION_DTYPE: LAMBDA(wxay, LET(bits, REGEXEXTRACT(wXaY, "a(\d+)"), SWITCH(bits, "4", "fp4", "8", "fp8", "16", "bf16", bits)))
Name REDUCE_SCATTER_CHIP2CHIP_TIME_MS: LAMBDA(global_data_traffic_size_in_mib, global_data_traffic_size_in_mib * 1024^2 / PARAMS("num_links_in_topo") / (2 * HW_SPEC("Chip-to-Chip ICI Bandwidth (uni, GB/s)") * 1024^3) * 1000)
Name REDUCE_SCATTER_CORE2CORE_TIME_MS: LAMBDA(global_data_traffic_in_mib, IF(global_data_traffic_in_mib=0, 0, global_data_traffic_in_mib * 1024^2 /(2 * HW_SPEC("Core-to-Core ICI Bandwidth (uni, GB/s)") *1024^3)*1000 ))
Name ALL_REDUCE_CORE2CORE_TIME_MS: LAMBDA(data_size_in_mib, 2 * data_size_in_mib * 1024^2 / ( 2 * HW_SPEC("Core-to-Core ICI Bandwidth (uni, GB/s)") *1024^3)*1000)
Name EXTRACT_WEIGHT_DTYPE: LAMBDA(wxay, LET(bits, REGEXEXTRACT(wXaY, "w(\d+)"), SWITCH(bits, "4", "fp4", "8", "fp8", "16", "bf16", bits)))
Name ALL2ALL_CHIP2CHIP_TIME_MS2: LAMBDA(data_size_in_mib, num_links, data_size_in_mib * 1024^2 /num_links / (2* HW_SPEC("Chip-to-Chip ICI Bandwidth (uni, GB/s)") *1024^3) *1000)
Name ALL_GATHER_CHIP2CHIP_TIME_MS: LAMBDA(global_data_traffic_size_in_mib, global_data_traffic_size_in_mib / PARAMS("num_links_in_topo") * 1024^2 /(2* HW_SPEC("Chip-to-Chip ICI Bandwidth (uni, GB/s)") *1024^3)*1000)
Name PAD_128: LAMBDA(val, CEILING(val, 128))
Name HBM_TIME_MS: LAMBDA(tensor_size_in_mib, tensor_size_in_mib * 1024^2 / ( VLOOKUP("Per-Core HBM-BW (GB/s)", INDIRECT("$F$16:$H$29"), 3, False) * 1024^3) * 1000)
Name PARAMS: LAMBDA(param_name, IF(ISNUMBER(param_name), param_name, vlookup(param_name,INDIRECT("$B$2:$C$43") ,2,FALSE) ))
Name ALL_GATHER_CORE2CORE_TIME_MS: LAMBDA(global_data_traffic_in_mib, global_data_traffic_in_mib * 1024^2 /(2 * HW_SPEC("Core-to-Core ICI Bandwidth (uni, GB/s)") *1024^3)*1000)
Name HW_SPEC: LAMBDA(spec_name, VLOOKUP(spec_name,INDIRECT("$F$16:$H$31"),3, False))
Name SHARDING: LAMBDA(param_name, IF(ISBLANK(param_name),1, vlookup(param_name, INDIRECT("$F$2:$G$10"),2,FALSE) ))
Name SIZEOF_IN_MIB: LAMBDA(param_name, dtype, PRODUCT( param_name) * vlookup(dtype,INDIRECT("$Q$2:$R$49") ,2,FALSE) / 1024^2)
Name COMPUTE_TIME_MS: LAMBDA(flops, mxu_dtype, flops / (VLOOKUP("Per-Core TFLOPS (" & mxu_dtype & ")",INDIRECT("$F$17:$H$43"),3,FALSE) * 1000000000000) * 1000)

Sheet Manual and Changelog
A1: How to use this spreadsheet:
A2: 1. Go to "Config and Summary" sheet and select from a preset configuration
B3: Final throughput can be found at the bottom
B4: Breakdown of operators can be found in "Decode [First/Last Token]" and "Prefill" sheets
A5: 2. You can add more configurations by adding new columns in the "Config and Summary" sheet and choosing it as the preset configuration
A8: Changelog
A9: [4/13/2026] | B9: miliu@ | C9: * Changed to use config based flow * Model first and last decode step time and interpolate overall step time * Updated theoretical A2A calculation based on bisection bandwidth for TPUs * Added support for GB200 based on NCCL look up table * Updated HBM/FLOPS derating for both GB200 and GFC based on measurements * Deprecated all other sheets
A10: [5/6/2026] | B10: miliu@ | C10: * Updated GB200 HBM capacity (GiB vs GB) * Added new dtype configurability for attention output projection (used in dsv3 nvfp4 v2 checkpoint)

Sheet Config and Summary
B1: Preset Selection: | C1: [1K/8K] GF 2x2x2 DP16/EP16 Aggregated MOE-a8w4 B=2.5K | F1: [1K/8K] GF 2x2 DP8/EP8 Aggregated MOE-a8w4 B=896 | H1: [1K/8K] GF 2x2x2 DP16/EP16 Aggregated MOE-a8w4 B=2.5K | J1: [1K/8K] GF 4x4 DP32/EP32 Aggregated MOE-a8w4 | L1: [1K/8K] GF 4x4x2 DP64/EP64 Aggregated MOE-a8w4 | N1: [1K/8K] GB200 4-chip DP4/EP4 Aggregated MOE-a4w4 | P1: [1K/8K] GB200 8-chip DP8/EP8 Aggregated MOE-a4w4 | R1: [1K/8K] GB200 16-chip DP16/EP16 Aggregated MOE-a4w4 | T1: [1K/8K] GB200 32-chip DP32/EP32 Aggregated MOE-a4w4 | V1: [1K/8K] GB200 32+4 Chips Disaggregated MOE-a4w4 | X1: [1K/8K] GB200 4-chip DP4/EP4 Aggregated MOE-a8w4 | Z1: [1K/8K] GB200 8-chip DP8/EP8 Aggregated MOE-a8w4 | AB1: [1K/8K] GB200 4-chip DP4/EP4 Aggregated MOE-a4w4 - Nsight
C2: Decode | D2: Prefill | F2: Decode | G2: Prefill | H2: Decode | I2: Prefill | J2: Decode | K2: Prefill | L2: Decode | M2: Prefill | N2: Decode | O2: Prefill | P2: Decode | Q2: Prefill | R2: Decode | S2: Prefill | T2: Decode | U2: Prefill | V2: Decode | W2: Prefill | X2: Decode | Y2: Prefill | Z2: Decode | AA2: Prefill | AB2: Decode | AC2: Prefill
A3: Device Assumptions
A4: Chip Name | C4: =XLOOKUP($C$1, $F$1:$AG$1, F4:AG4) -> GhostFish (P3) Derated | D4: =XLOOKUP($C$1, $F$1:$AG$1, G4:AH4) -> GhostFish (P3) Derated | F4: GhostFish (P3) Derated | G4: GhostFish (P3) Derated | H4: GhostFish (P3) Derated | I4: GhostFish (P3) Derated | J4: GhostFish (P3) Derated | K4: GhostFish (P3) Derated | L4: GhostFish (P3) Derated | M4: GhostFish (P3) Derated | N4: GB200 Derated | O4: GB200 Derated | P4: GB200 Derated | Q4: GB200 Derated | R4: GB200 Derated | S4: GB200 Derated | T4: GB200 Derated | U4: GB200 Derated | V4: GB200 Derated | W4: GB200 Derated | X4: GB200 Derated | Y4: GB200 Derated | Z4: GB200 Derated | AA4: GB200 Derated | AB4: GB200 Derated | AC4: GB200 Derated
A5: Use Measured NCCL Lookup Table | C5: =XLOOKUP($C$1, $F$1:$AG$1, F5:AG5) -> FALSE | D5: =XLOOKUP($C$1, $F$1:$AG$1, G5:AH5) -> FALSE | F5: FALSE | G5: FALSE | H5: FALSE | I5: FALSE | J5: FALSE | K5: FALSE | L5: FALSE | M5: FALSE | N5: TRUE | O5: TRUE | P5: TRUE | Q5: TRUE | R5: TRUE | S5: TRUE | T5: TRUE | U5: TRUE | V5: TRUE | W5: TRUE | X5: TRUE | Y5: TRUE | Z5: TRUE | AA5: TRUE | AB5: TRUE | AC5: TRUE
C6: =XLOOKUP($C$1, $F$1:$AG$1, F6:AG6) | D6: =XLOOKUP($C$1, $F$1:$AG$1, G6:AH6)
A7: Sharding (Axis Name, # of Devices) | C7: =XLOOKUP($C$1, $F$1:$AG$1, F7:AG7) | D7: =XLOOKUP($C$1, $F$1:$AG$1, G7:AH7)
A8: model | C8: =XLOOKUP($C$1, $F$1:$AG$1, F8:AG8) -> 1 | D8: =XLOOKUP($C$1, $F$1:$AG$1, G8:AH8) -> 1 | F8: 1 | G8: 1 | H8: 1 | I8: 1 | J8: 1 | K8: 1 | L8: 1 | M8: 1 | N8: 1 | O8: 1 | P8: 1 | Q8: 1 | R8: 1 | S8: 1 | T8: 1 | U8: 1 | V8: 1 | W8: 1 | X8: 1 | Y8: 1 | Z8: 1 | AA8: 1 | AB8: 1 | AC8: 1
A9: data | C9: =XLOOKUP($C$1, $F$1:$AG$1, F9:AG9) -> 16 | D9: =XLOOKUP($C$1, $F$1:$AG$1, G9:AH9) -> 16 | F9: 8 | G9: 8 | H9: 16 | I9: 16 | J9: 32 | K9: 32 | L9: 64 | M9: 64 | N9: 4 | O9: 4 | P9: 8 | Q9: 8 | R9: 16 | S9: 16 | T9: 32 | U9: 32 | V9: 32 | W9: 4 | X9: 4 | Y9: 4 | Z9: 8 | AA9: 8 | AB9: 4 | AC9: 4
A10: seq | C10: =XLOOKUP($C$1, $F$1:$AG$1, F10:AG10) -> 1 | D10: =XLOOKUP($C$1, $F$1:$AG$1, G10:AH10) -> 1 | F10: 1 | G10: 1 | H10: 1 | I10: 1 | J10: 1 | K10: 1 | L10: 1 | M10: 1 | N10: 1 | O10: 1 | P10: 1 | Q10: 1 | R10: 1 | S10: 1 | T10: 1 | U10: 1 | V10: 1 | W10: 1 | X10: 1 | Y10: 1 | Z10: 1 | AA10: 1 | AB10: 1 | AC10: 1
A11: attn_model | C11: =XLOOKUP($C$1, $F$1:$AG$1, F11:AG11) -> 1 | D11: =XLOOKUP($C$1, $F$1:$AG$1, G11:AH11) -> 1 | F11: 1 | G11: 1 | H11: 1 | I11: 1 | J11: 1 | K11: 1 | L11: 1 | M11: 1 | N11: 1 | O11: 1 | P11: 1 | Q11: 1 | R11: 1 | S11: 1 | T11: 1 | U11: 1 | V11: 1 | W11: 1 | X11: 1 | Y11: 1 | Z11: 1 | AA11: 1 | AB11: 1 | AC11: 1
C12: =XLOOKUP($C$1, $F$1:$AG$1, F12:AG12) | D12: =XLOOKUP($C$1, $F$1:$AG$1, G12:AH12)
A13: Serving Configuration and Strategy | C13: =XLOOKUP($C$1, $F$1:$AG$1, F13:AG13) | D13: =XLOOKUP($C$1, $F$1:$AG$1, G13:AH13)
A14: Sequence Length (Q) | B14: T | C14: =XLOOKUP($C$1, $F$1:$AG$1, F14:AG14) -> 1 | D14: =XLOOKUP($C$1, $F$1:$AG$1, G14:AH14) -> 1024 | F14: 1 | G14: =F17 -> 1024 | H14: 1 | I14: =H17 -> 1024 | J14: 1 | K14: =J17 -> 1024 | L14: 1 | M14: =L17 -> 1024 | N14: 1 | O14: =N17 -> 1024 | P14: 1 | Q14: =P17 -> 1024 | R14: 1 | S14: =R17 -> 1024 | T14: 1 | U14: =T17 -> 1024 | V14: 1 | W14: =V17 -> 1024 | X14: 1 | Y14: =X17 -> 1024 | Z14: 1 | AA14: =Z17 -> 1024 | AB14: 1 | AC14: =AB17 -> 1024
A15: Batch Size (power of 2) | B15: B | C15: =XLOOKUP($C$1, $F$1:$AG$1, F15:AG15) -> 2560 | D15: =XLOOKUP($C$1, $F$1:$AG$1, G15:AH15) -> 16 | F15: 896 | G15: 8 | H15: =2048+512 -> 2560 | I15: 16 | J15: =4096+2048+1024 -> 7168 | K15: 32 | L15: 12288 | M15: 64 | N15: =224*4 -> 896 | O15: 4 | P15: =2048+512 -> 2560 | Q15: 8 | R15: 7168 | S15: 16 | T15: 12288 | U15: 32 | V15: 8192 | W15: 16 | X15: =224*4 -> 896 | Y15: 8 | Z15: =2048+512 -> 2560 | AA15: 8 | AB15: =220*4 -> 880 | AC15: 4
A16: Sequence Length (KV) | B16: S | C16: =XLOOKUP($C$1, $F$1:$AG$1, F16:AG16) -> 9216 | D16: =XLOOKUP($C$1, $F$1:$AG$1, G16:AH16) -> 1024 | F16: =9*1024 -> 9216 | G16: =G14 -> 1024 | H16: =1024+8192 -> 9216 | I16: =I14 -> 1024 | J16: =9*1024 -> 9216 | K16: =K14 -> 1024 | L16: =1024+8192 -> 9216 | M16: =M14 -> 1024 | N16: =9*1024 -> 9216 | O16: =O14 -> 1024 | P16: =1024+8192 -> 9216 | Q16: =Q14 -> 1024 | R16: =9*1024 -> 9216 | S16: =S14 -> 1024 | T16: =9*1024 -> 9216 | U16: =U14 -> 1024 | V16: =1024+8192 -> 9216 | W16: =W14 -> 1024 | X16: =1024+8192 -> 9216 | Y16: =Y14 -> 1024 | Z16: =1024+8192 -> 9216 | AA16: =AA14 -> 1024 | AB16: =6*1024 -> 6144 | AC16: =AC14 -> 1024
A17: Sequence Length (KV) - First Token Decode | B17: S_first | C17: =XLOOKUP($C$1, $F$1:$AG$1, F17:AG17) -> 1024 | D17: =XLOOKUP($C$1, $F$1:$AG$1, G17:AH17) -> N/A | F17: 1024 | G17: N/A | H17: 1024 | I17: N/A | J17: 1024 | K17: N/A | L17: 1024 | M17: N/A | N17: 1024 | O17: N/A | P17: 1024 | Q17: N/A | R17: 1024 | S17: N/A | T17: 1024 | U17: N/A | V17: 1024 | W17: N/A | X17: 1024 | Y17: N/A | Z17: 1024 | AA17: N/A | AB17: 1024 | AC17: N/A
A18: Scheduler Latency Overhead | C18: =XLOOKUP($C$1, $F$1:$AG$1, F18:AG18) -> 0 | D18: =XLOOKUP($C$1, $F$1:$AG$1, G18:AH18) -> 0 | F18: 0 | G18: 0 | H18: 0 | I18: 0 | J18: 0 | K18: 0 | L18: 0 | M18: 0 | N18: 0 | O18: 0 | P18: 0 | Q18: 0 | R18: 0 | S18: 0 | T18: 0 | U18: 0 | V18: 0 | W18: 0 | X18: 0 | Y18: 0 | Z18: 0 | AA18: 0 | AB18: 0 | AC18: 0
A19: Roofline Discount Rate | C19: =XLOOKUP($C$1, $F$1:$AG$1, F19:AG19) -> 1 | D19: =XLOOKUP($C$1, $F$1:$AG$1, G19:AH19) -> 1 | F19: 1 | G19: 1 | H19: 1 | I19: 1 | J19: 1 | K19: 1 | L19: 1 | M19: 1 | N19: 1 | O19: 1 | P19: 1 | Q19: 1 | R19: 1 | S19: 1 | T19: 1 | U19: 1 | V19: 1 | W19: 1 | X19: 1 | Y19: 1 | Z19: 1 | AA19: 1 | AB19: 1 | AC19: 1
A20: Flash Attention Enabled | B20: flash_attn | C20: =XLOOKUP($C$1, $F$1:$AG$1, F20:AG20) -> TRUE | D20: =XLOOKUP($C$1, $F$1:$AG$1, G20:AH20) -> TRUE | F20: TRUE | G20: TRUE | H20: TRUE | I20: TRUE | J20: TRUE | K20: TRUE | L20: TRUE | M20: TRUE | N20: TRUE | O20: TRUE | P20: TRUE | Q20: TRUE | R20: TRUE | S20: TRUE | T20: TRUE | U20: TRUE | V20: TRUE | W20: TRUE | X20: TRUE | Y20: TRUE | Z20: TRUE | AA20: TRUE | AB20: TRUE | AC20: TRUE
A21: Enforce Perfect Expert Routing | B21: enforce_perfect_expert_routing | C21: =XLOOKUP($C$1, $F$1:$AG$1, F21:AG21) -> TRUE | D21: =XLOOKUP($C$1, $F$1:$AG$1, G21:AH21) -> TRUE | F21: TRUE | G21: TRUE | H21: TRUE | I21: TRUE | J21: TRUE | K21: TRUE | L21: TRUE | M21: TRUE | N21: TRUE | O21: TRUE | P21: TRUE | Q21: TRUE | R21: TRUE | S21: TRUE | T21: TRUE | U21: TRUE | V21: TRUE | W21: TRUE | X21: TRUE | Y21: TRUE | Z21: TRUE | AA21: TRUE | AB21: TRUE | AC21: TRUE
A22: MOE Token Dispatch Strategy | C22: =XLOOKUP($C$1, $F$1:$AG$1, F22:AG22) -> Strategy C: Hirarachical All-Gather | D22: =XLOOKUP($C$1, $F$1:$AG$1, G22:AH22) -> Strategy C: Hirarachical All-Gather | F22: Strategy C: Hirarachical All-Gather | G22: Strategy C: Hirarachical All-Gather | H22: Strategy C: Hirarachical All-Gather | I22: Strategy C: Hirarachical All-Gather | J22: Strategy C: Hirarachical All-Gather | K22: Strategy C: Hirarachical All-Gather | L22: Strategy A: All-To-All | M22: Strategy A: All-To-All | N22: Strategy A: All-To-All | O22: Strategy A: All-To-All | P22: Strategy A: All-To-All | Q22: Strategy A: All-To-All | R22: Strategy A: All-To-All | S22: Strategy A: All-To-All | T22: Strategy A: All-To-All | U22: Strategy A: All-To-All | V22: Strategy A: All-To-All | W22: Strategy A: All-To-All | X22: Strategy A: All-To-All | Y22: Strategy A: All-To-All | Z22: Strategy A: All-To-All | AA22: Strategy A: All-To-All | AB22: Strategy A: All-To-All | AC22: Strategy A: All-To-All
A23: MOE Token Collect Strategy | C23: =XLOOKUP($C$1, $F$1:$AG$1, F23:AG23) -> Option C: Hierachical RS | D23: =XLOOKUP($C$1, $F$1:$AG$1, G23:AH23) -> Option C: Hierachical RS | F23: Option C: Hierachical RS | G23: Option C: Hierachical RS | H23: Option C: Hierachical RS | I23: Option C: Hierachical RS | J23: Option C: Hierachical RS | K23: Option C: Hierachical RS | L23: Option A: Transposed All-To-All | M23: Option A: Transposed All-To-All | N23: Option A: Transposed All-To-All | O23: Option A: Transposed All-To-All | P23: Option A: Transposed All-To-All | Q23: Option A: Transposed All-To-All | R23: Option A: Transposed All-To-All | S23: Option A: Transposed All-To-All | T23: Option A: Transposed All-To-All | U23: Option A: Transposed All-To-All | V23: Option A: Transposed All-To-All | W23: Option A: Transposed All-To-All | X23: Option A: Transposed All-To-All | Y23: Option A: Transposed All-To-All | Z23: Option A: Transposed All-To-All | AA23: Option A: Transposed All-To-All | AB23: Option A: Transposed All-To-All | AC23: Option A: Transposed All-To-All
A24: MOE Collective Overlap Strategy | C24: =XLOOKUP($C$1, $F$1:$AG$1, F24:AG24) -> OptionA. No Overlapping | D24: =XLOOKUP($C$1, $F$1:$AG$1, G24:AH24) -> OptionA. No Overlapping | F24: OptionA. No Overlapping | G24: OptionA. No Overlapping | H24: OptionA. No Overlapping | I24: OptionA. No Overlapping | J24: OptionA. No Overlapping | K24: OptionA. No Overlapping | L24: OptionA. No Overlapping | M24: OptionA. No Overlapping | N24: OptionA. No Overlapping | O24: OptionA. No Overlapping | P24: OptionA. No Overlapping | Q24: OptionA. No Overlapping | R24: OptionA. No Overlapping | S24: OptionA. No Overlapping | T24: OptionA. No Overlapping | U24: OptionA. No Overlapping | V24: OptionA. No Overlapping | W24: OptionA. No Overlapping | X24: OptionA. No Overlapping | Y24: OptionA. No Overlapping | Z24: OptionA. No Overlapping | AA24: OptionA. No Overlapping | AB24: OptionA. No Overlapping | AC24: OptionA. No Overlapping
C25: =XLOOKUP($C$1, $F$1:$AG$1, F25:AG25) | D25: =XLOOKUP($C$1, $F$1:$AG$1, G25:AH25)
A26: Numerics | C26: =XLOOKUP($C$1, $F$1:$AG$1, F26:AG26) | D26: =XLOOKUP($C$1, $F$1:$AG$1, G26:AH26)
A27: KV Cache dtype | B27: kv_dtype | C27: =XLOOKUP($C$1, $F$1:$AG$1, F27:AG27) -> fp8 | D27: =XLOOKUP($C$1, $F$1:$AG$1, G27:AH27) -> fp8 | F27: fp8 | G27: fp8 | H27: fp8 | I27: fp8 | J27: fp8 | K27: fp8 | L27: fp8 | M27: fp8 | N27: fp8 | O27: fp8 | P27: fp8 | Q27: fp8 | R27: fp8 | S27: fp8 | T27: fp8 | U27: fp8 | V27: fp8 | W27: fp8 | X27: fp8 | Y27: fp8 | Z27: fp8 | AA27: fp8 | AB27: fp8 | AC27: fp8
A28: Attention Projections Numeric | B28: attn_proj_dtype | C28: =XLOOKUP($C$1, $F$1:$AG$1, F28:AG28) -> w8a8 | D28: =XLOOKUP($C$1, $F$1:$AG$1, G28:AH28) -> w8a8 | F28: w8a8 | G28: w8a8 | H28: w8a8 | I28: w8a8 | J28: w8a8 | K28: w8a8 | L28: w8a8 | M28: w8a8 | N28: w16a16 | O28: w16a16 | P28: w16a16 | Q28: w16a16 | R28: w16a16 | S28: w16a16 | T28: w16a16 | U28: w16a16 | V28: w16a16 | W28: w16a16 | X28: w16a16 | Y28: w16a16 | Z28: w16a16 | AA28: w16a16 | AB28: w16a16 | AC28: w16a16
A29: Attention Output Projection Numerics | B29: attn_oproj_dtype | C29: =XLOOKUP($C$1, $F$1:$AG$1, F29:AG29) -> w8a8 | D29: =XLOOKUP($C$1, $F$1:$AG$1, G29:AH29) -> w8a8 | F29: w8a8 | G29: w8a8 | H29: w8a8 | I29: w8a8 | J29: w8a8 | K29: w8a8 | L29: w8a8 | M29: w8a8 | N29: w4a4 | O29: w4a4 | P29: w4a4 | Q29: w4a4 | R29: w4a4 | S29: w4a4 | T29: w4a4 | U29: w4a4 | V29: w4a4 | W29: w4a4 | X29: w4a4 | Y29: w4a4 | Z29: w4a4 | AA29: w4a4 | AB29: w4a4 | AC29: w4a4
A30: Attention "K" numeric from KV | B30: attn_kv_k_dtype | C30: =XLOOKUP($C$1, $F$1:$AG$1, F30:AG30) -> fp8 | D30: =XLOOKUP($C$1, $F$1:$AG$1, G30:AH30) -> fp8 | F30: fp8 | G30: fp8 | H30: fp8 | I30: fp8 | J30: fp8 | K30: fp8 | L30: fp8 | M30: fp8 | N30: fp8 | O30: fp8 | P30: fp8 | Q30: fp8 | R30: fp8 | S30: fp8 | T30: fp8 | U30: fp8 | V30: fp8 | W30: fp8 | X30: fp8 | Y30: fp8 | Z30: fp8 | AA30: fp8 | AB30: fp8 | AC30: fp8
A31: Attention "A" numeric from AV | B31: attn_av_a_dtype | C31: =XLOOKUP($C$1, $F$1:$AG$1, F31:AG31) -> fp8 | D31: =XLOOKUP($C$1, $F$1:$AG$1, G31:AH31) -> fp8 | F31: fp8 | G31: fp8 | H31: fp8 | I31: fp8 | J31: fp8 | K31: fp8 | L31: fp8 | M31: fp8 | N31: fp8 | O31: fp8 | P31: fp8 | Q31: fp8 | R31: fp8 | S31: fp8 | T31: fp8 | U31: fp8 | V31: fp8 | W31: fp8 | X31: fp8 | Y31: fp8 | Z31: fp8 | AA31: fp8 | AB31: fp8 | AC31: fp8
A32: Expert Dispatch Numeric | B32: expert_dispatch_dtype | C32: =XLOOKUP($C$1, $F$1:$AG$1, F32:AG32) -> fp8 | D32: =XLOOKUP($C$1, $F$1:$AG$1, G32:AH32) -> fp8 | F32: fp8 | G32: fp8 | H32: fp8 | I32: fp8 | J32: fp8 | K32: fp8 | L32: fp8 | M32: fp8 | N32: fp8 | O32: fp8 | P32: fp8 | Q32: fp8 | R32: fp8 | S32: fp8 | T32: fp8 | U32: fp8 | V32: fp8 | W32: fp8 | X32: fp8 | Y32: fp8 | Z32: fp8 | AA32: fp8 | AB32: fp8 | AC32: fp8
A33: MoE Numeric | B33: moe_dtype | C33: =XLOOKUP($C$1, $F$1:$AG$1, F33:AG33) -> w4a8 | D33: =XLOOKUP($C$1, $F$1:$AG$1, G33:AH33) -> w4a8 | F33: w4a8 | G33: w4a8 | H33: w4a8 | I33: w4a8 | J33: w4a8 | K33: w4a8 | L33: w4a8 | M33: w4a8 | N33: w4a4 | O33: w4a4 | P33: w4a4 | Q33: w4a4 | R33: w4a4 | S33: w4a4 | T33: w4a4 | U33: w4a4 | V33: w4a4 | W33: w4a4 | X33: w4a8 | Y33: w4a8 | Z33: w4a8 | AA33: w4a8 | AB33: w4a4 | AC33: w4a4
A34: Expert Collect Numeric | B34: expert_collect_dtype | C34: =XLOOKUP($C$1, $F$1:$AG$1, F34:AG34) -> bf16 | D34: =XLOOKUP($C$1, $F$1:$AG$1, G34:AH34) -> bf16 | F34: bf16 | G34: bf16 | H34: bf16 | I34: bf16 | J34: bf16 | K34: bf16 | L34: bf16 | M34: bf16 | N34: bf16 | O34: bf16 | P34: bf16 | Q34: bf16 | R34: bf16 | S34: bf16 | T34: bf16 | U34: bf16 | V34: bf16 | W34: bf16 | X34: bf16 | Y34: bf16 | Z34: bf16 | AA34: bf16 | AB34: bf16 | AC34: bf16
A36: Results
B38: Decode - First Token | C38: Decode - Last Token | D38: Prefill
A39: Memory Occupancy OK | B39: ='Decode First Token'!B94 -> TRUE | C39: ='Decode Last Token'!B94 -> TRUE | D39: =Prefill!B94 -> TRUE
A40: E2E Latency (s) | B40: ='Decode First Token'!B48 -> 0.024513179 | C40: ='Decode Last Token'!B48 -> 0.038873086 | D40: =Prefill!B48 -> 0.12789496
A41: Throughput (tokens/s) | B41: ='Decode First Token'!B49 -> 104433.62 | C41: ='Decode Last Token'!B49 -> 65855.332 | D41: =Prefill!B49 -> 128105.12
A42: Discounted Throughput (tokens/s) | B42: ='Decode First Token'!B50 -> 104433.62 | C42: ='Decode Last Token'!B50 -> 65855.332 | D42: =Prefill!B50 -> 128105.12
...

Sheet Decode First Token
A1: Contact: donghyun@, gpolovets@, miliu@. Feedback/Bug reports are welcome!
A2: Description | B2: Symbol | C2: Value | F2: Sharding (Axis Name) | G2: # of Devices | H2: Notes | Q2: Size In Bytes | T2: MXU dtype
A3: Embedding Dimension | B3: D | C3: 7168 | F3: [ ↓ Configurable Values] | Q3: fp4 | R3: 0.5 | T3: =U3&","&V3 -> fp4,fp4 | U3: fp4 | V3: fp4 | W3: fp4
A4: Hidden Dimension | B4: F | C4: 2048 | F4: model | G4: ='Config and Summary'!$C8 -> 1 | Q4: fp8 | R4: 1 | T4: =U4&","&V4 -> fp4,fp8 | U4: fp4 | V4: fp8 | W4: fp8
A5: # of experts | B5: E | C5: 256 | F5: data | G5: ='Config and Summary'!$C9 -> 16 | H5: Also used for expert sharding for MoE | Q5: bf16 | R5: 2 | T5: =U5&","&V5 -> fp4,bf16 | U5: fp4 | V5: bf16 | W5: bf16
A6: # of Layers | B6: L | C6: 61 | F6: seq | G6: ='Config and Summary'!$C10 -> 1 | T6: =U6&","&V6 -> fp8,fp4 | U6: fp8 | V6: fp4 | W6: fp8
A7: # of Dense Layers | B7: DL | C7: 3 | F7: attn_model | G7: ='Config and Summary'!$C11 -> 1 | H7: Used if attention is replicated | T7: =U7&","&V7 -> fp8,fp8 | U7: fp8 | V7: fp8 | W7: fp8
A8: # of experts to be activated per token | B8: top_k | C8: 8 | F8: [ ↓ Derived Values]
A9: The dimension of the compressed latent vector for Query | B9: c_q | C9: 1536 | F9: data,model | G9: =G5*G4 -> 16 | T9: =U9&","&V9 -> fp8,bf16 | U9: fp8 | V9: bf16 | W9: bf16
A10: The dimension of the compressed latent vector for KV | B10: c_kv | C10: 512 | F10: Total # of devices | G10: =PRODUCT(G3:G6) -> 16 | T10: =U10&","&V10 -> bf16,fp4 | U10: bf16 | V10: fp4 | W10: bf16
A11: The dimension of Non-RoPE part of the query head | B11: h_nope | C11: 128 | F11: Total # of chips | G11: =$G$10/$H$18 -> 8 | T11: =U11&","&V11 -> bf16,fp8 | U11: bf16 | V11: fp8 | W11: bf16
A12: The dimension of the RoPE part of the query head | B12: h_rope | C12: 64 | T12: bf16,bf16 | U12: bf16 | V12: bf16 | W12: bf16
A13: The number of Attention Heads (Query) | B13: n_q | C13: 128
A14: [ ↓ Derived parameters]
A15: h_nope+h_rope | B15: h_nope+h_rope | C15: =$C$11+$C$12 -> 192
A16: c_kv+h_rope | B16: c_kv+h_rope | C16: =$C$10+$C$12 -> 576
A17: # of Duplicated tokens (top_k times) | B17: kT | C17: =C8*$C$25 -> 8 | F17: Hardware Spec | H17: ='Config and Summary'!C4 -> GhostFish (P3) Derated
A18: # of Devices | B18: num_devices | C18: =$G$10 -> 16 | F18: {=DB!A2:A16} -> # of TensorCore per Chip | H18: {=xlookup($H$17,DB!1:1,DB!2:16)} -> 2
A19: # of Chips | B19: num_chips | C19: =$G$11 -> 8 | F19: Per-Chip HBM-BW (GB/s) | H19: 6729.8
A20: [TPU] Assumed Topology | B20: topo | C20: =vlookup(C19, DB!$A$26:$F$31, 5, False) -> 2x2x2 | F20: Per-Chip TFLOPS (fp4) | H20: 3571.236
A21: [TPU] Total # of Bidir Links | B21: num_links_in_topo | C21: =vlookup(C19, DB!$A$26:$F$31, 6, False) -> 12 | F21: Per-Chip TFLOPS (fp8) | H21: 3571.236
F22: Per-Chip TFLOPS (fp16) | H22: 1785.618
A23: [ ↓ Configurable parameters] | F23: Per-Chip HBM Capacity (GiB) | H23: 192
A24: Regime | B24: R | C24: Decode | F24: Per-Core HBM-BW (GB/s) | H24: 3364.9
A25: Sequence Length (Q) | B25: T | C25: ='Config and Summary'!C14 -> 1 | F25: Per-Core TFLOPS (fp4) | H25: 1785.618
A26: Batch Size (power of 2) | B26: B | C26: ='Config and Summary'!C15 -> 2560 | F26: Per-Core TFLOPS (fp8) | H26: 1785.618
A27: Sequence Length (KV) | B27: S | C27: ='Config and Summary'!C17 -> 1024 | D27: Use the first token KV length | F27: Per-Core TFLOPS (bf16) | H27: 892.809
A28: Scheduler Latency Overhead | C28: ='Config and Summary'!C18 -> 0 | F28: Per-Core HBM Capacity (GiB) | H28: 96
A29: Roofline Discount Rate | C29: ='Config and Summary'!C19 -> 1 | F29: Core-to-Core ICI Bandwidth (uni, GB/s) | H29: 600
A30: Flash Attention Enabled | B30: flash_attn | C30: ='Config and Summary'!C20 -> TRUE | F30: Chip-to-Chip ICI Bandwidth (uni, GB/s) | H30: 80
A31: Enforce Perfect Expert Routing | B31: enforce_perfect_expert_routing | C31: ='Config and Summary'!C21 -> TRUE | F31: Chip-to-Chip ICI Latency (ms) | H31: 0.0013
A32: [ ↓ Configurable Numeric] | F32: Min MXU Contracting Dim | H32: 256
A33: KV Cache dtype | B33: kv_dtype | C33: ='Config and Summary'!C27 -> fp8
A34: Attention Projections Numeric | B34: attn_proj_dtype | C34: ='Config and Summary'!C28 -> w8a8
A35: Attention Output Projection Numerics | B35: attn_oproj_dtype | C35: ='Config and Summary'!C29 -> w8a8
A36: Attention "K" numeric from KV | B36: attn_kv_k_dtype | C36: ='Config and Summary'!C30 -> fp8
A37: Attention "A" numeric from AV | B37: attn_av_a_dtype | C37: ='Config and Summary'!C31 -> fp8
A38: Expert Dispatch Numeric | B38: expert_dispatch_dtype | C38: ='Config and Summary'!C32 -> fp8
A39: MoE Numeric | B39: moe_dtype | C39: ='Config and Summary'!C33 -> w4a8
A40: Expert Collect Numeric | B40: expert_collect_dtype | C40: ='Config and Summary'!C34 -> bf16
...

Sheet Decode Last Token
A1: Contact: donghyun@, gpolovets@, miliu@. Feedback/Bug reports are welcome!
A2: Description | B2: Symbol | C2: Value | F2: Sharding (Axis Name) | G2: # of Devices | H2: Notes | Q2: Size In Bytes | T2: MXU dtype
A3: Embedding Dimension | B3: D | C3: 7168 | F3: [ ↓ Configurable Values] | Q3: fp4 | R3: 0.5 | T3: =U3&","&V3 -> fp4,fp4 | U3: fp4 | V3: fp4 | W3: fp4
A4: Hidden Dimension | B4: F | C4: 2048 | F4: model | G4: ='Config and Summary'!$C8 -> 1 | Q4: fp8 | R4: 1 | T4: =U4&","&V4 -> fp4,fp8 | U4: fp4 | V4: fp8 | W4: fp8
A5: # of experts | B5: E | C5: 256 | F5: data | G5: ='Config and Summary'!$C9 -> 16 | H5: Also used for expert sharding for MoE | Q5: bf16 | R5: 2 | T5: =U5&","&V5 -> fp4,bf16 | U5: fp4 | V5: bf16 | W5: bf16
A6: # of Layers | B6: L | C6: 61 | F6: seq | G6: ='Config and Summary'!$C10 -> 1 | T6: =U6&","&V6 -> fp8,fp4 | U6: fp8 | V6: fp4 | W6: fp8
A7: # of Dense Layers | B7: DL | C7: 3 | F7: attn_model | G7: ='Config and Summary'!$C11 -> 1 | H7: Used if attention is replicated | T7: =U7&","&V7 -> fp8,fp8 | U7: fp8 | V7: fp8 | W7: fp8
A8: # of experts to be activated per token | B8: top_k | C8: 8 | F8: [ ↓ Derived Values]
A9: The dimension of the compressed latent vector for Query | B9: c_q | C9: 1536 | F9: data,model | G9: =G5*G4 -> 16 | T9: =U9&","&V9 -> fp8,bf16 | U9: fp8 | V9: bf16 | W9: bf16
A10: The dimension of the compressed latent vector for KV | B10: c_kv | C10: 512 | F10: Total # of devices | G10: =PRODUCT(G3:G6) -> 16 | T10: =U10&","&V10 -> bf16,fp4 | U10: bf16 | V10: fp4 | W10: bf16
A11: The dimension of Non-RoPE part of the query head | B11: h_nope | C11: 128 | F11: Total # of chips | G11: =$G$10/$H$18 -> 8 | T11: =U11&","&V11 -> bf16,fp8 | U11: bf16 | V11: fp8 | W11: bf16
A12: The dimension of the RoPE part of the query head | B12: h_rope | C12: 64 | T12: bf16,bf16 | U12: bf16 | V12: bf16 | W12: bf16
A13: The number of Attention Heads (Query) | B13: n_q | C13: 128
A14: [ ↓ Derived parameters]
A15: h_nope+h_rope | B15: h_nope+h_rope | C15: =$C$11+$C$12 -> 192
A16: c_kv+h_rope | B16: c_kv+h_rope | C16: =$C$10+$C$12 -> 576
A17: # of Duplicated tokens (top_k times) | B17: kT | C17: =C8*$C$25 -> 8 | F17: Hardware Spec | H17: ='Config and Summary'!C4 -> GhostFish (P3) Derated
A18: # of Devices | B18: num_devices | C18: =$G$10 -> 16 | F18: {=DB!A2:A16} -> # of TensorCore per Chip | H18: {=xlookup($H$17,DB!1:1,DB!2:16)} -> 2
A19: # of Chips | B19: num_chips | C19: =$G$11 -> 8 | F19: Per-Chip HBM-BW (GB/s) | H19: 6729.8
A20: [TPU] Assumed Topology | B20: topo | C20: =vlookup(C19, DB!$A$26:$F$31, 5, False) -> 2x2x2 | F20: Per-Chip TFLOPS (fp4) | H20: 3571.236
A21: [TPU] Total # of Bidir Links | B21: num_links_in_topo | C21: =vlookup(C19, DB!$A$26:$F$31, 6, False) -> 12 | F21: Per-Chip TFLOPS (fp8) | H21: 3571.236
F22: Per-Chip TFLOPS (fp16) | H22: 1785.618
A23: [ ↓ Configurable parameters] | F23: Per-Chip HBM Capacity (GiB) | H23: 192
A24: Regime | B24: R | C24: Decode | F24: Per-Core HBM-BW (GB/s) | H24: 3364.9
A25: Sequence Length (Q) | B25: T | C25: ='Config and Summary'!C14 -> 1 | F25: Per-Core TFLOPS (fp4) | H25: 1785.618
A26: Batch Size (power of 2) | B26: B | C26: ='Config and Summary'!C15 -> 2560 | F26: Per-Core TFLOPS (fp8) | H26: 1785.618
A27: Sequence Length (KV) | B27: S | C27: ='Config and Summary'!C16 -> 9216 | F27: Per-Core TFLOPS (bf16) | H27: 892.809
A28: Scheduler Latency Overhead | C28: ='Config and Summary'!C18 -> 0 | F28: Per-Core HBM Capacity (GiB) | H28: 96
A29: Roofline Discount Rate | C29: ='Config and Summary'!C19 -> 1 | F29: Core-to-Core ICI Bandwidth (uni, GB/s) | H29: 600
A30: Flash Attention Enabled | B30: flash_attn | C30: ='Config and Summary'!C20 -> TRUE | F30: Chip-to-Chip ICI Bandwidth (uni, GB/s) | H30: 80
A31: Enforce Perfect Expert Routing | B31: enforce_perfect_expert_routing | C31: ='Config and Summary'!C21 -> TRUE | F31: Chip-to-Chip ICI Latency (ms) | H31: 0.0013
A32: [ ↓ Configurable Numeric] | F32: Min MXU Contracting Dim | H32: 256
A33: KV Cache dtype | B33: kv_dtype | C33: ='Config and Summary'!C27 -> fp8
A34: Attention Projections Numeric | B34: attn_proj_dtype | C34: ='Config and Summary'!C28 -> w8a8
A35: Attention Output Projection Numerics | B35: attn_oproj_dtype | C35: ='Config and Summary'!C29 -> w8a8
A36: Attention "K" numeric from KV | B36: attn_kv_k_dtype | C36: ='Config and Summary'!C30 -> fp8
A37: Attention "A" numeric from AV | B37: attn_av_a_dtype | C37: ='Config and Summary'!C31 -> fp8
A38: Expert Dispatch Numeric | B38: expert_dispatch_dtype | C38: ='Config and Summary'!C32 -> fp8
A39: MoE Numeric | B39: moe_dtype | C39: ='Config and Summary'!C33 -> w4a8
A40: Expert Collect Numeric | B40: expert_collect_dtype | C40: ='Config and Summary'!C34 -> bf16
...

Sheet Prefill
A1: Contact: donghyun@, gpolovets@, miliu@. Feedback/Bug reports are welcome!
A2: Description | B2: Symbol | C2: Value | F2: Sharding (Axis Name) | G2: # of Devices | H2: Notes | Q2: Size In Bytes | T2: MXU dtype
A3: Embedding Dimension | B3: D | C3: 7168 | F3: [ ↓ Configurable Values] | Q3: fp4 | R3: 0.5 | T3: =U3&","&V3 -> fp4,fp4 | U3: fp4 | V3: fp4 | W3: fp4
A4: Hidden Dimension | B4: F | C4: 2048 | F4: model | G4: ='Config and Summary'!$D8 -> 1 | Q4: fp8 | R4: 1 | T4: =U4&","&V4 -> fp4,fp8 | U4: fp4 | V4: fp8 | W4: fp8
A5: # of experts | B5: E | C5: 256 | F5: data | G5: ='Config and Summary'!$D9 -> 16 | H5: Also used for expert sharding for MoE | Q5: bf16 | R5: 2 | T5: =U5&","&V5 -> fp4,bf16 | U5: fp4 | V5: bf16 | W5: bf16
A6: # of Layers | B6: L | C6: 61 | F6: seq | G6: ='Config and Summary'!$D10 -> 1 | T6: =U6&","&V6 -> fp8,fp4 | U6: fp8 | V6: fp4 | W6: fp8
A7: # of Dense Layers | B7: DL | C7: 3 | F7: attn_model | G7: ='Config and Summary'!$D11 -> 1 | H7: Used if attention is replicated | T7: =U7&","&V7 -> fp8,fp8 | U7: fp8 | V7: fp8 | W7: fp8
A8: # of experts to be activated per token | B8: top_k | C8: 8 | F8: [ ↓ Derived Values]
A9: The dimension of the compressed latent vector for Query | B9: c_q | C9: 1536 | F9: data,model | G9: =G5*G4 -> 16 | T9: =U9&","&V9 -> fp8,bf16 | U9: fp8 | V9: bf16 | W9: bf16
A10: The dimension of the compressed latent vector for KV | B10: c_kv | C10: 512 | F10: Total # of devices | G10: =PRODUCT(G3:G6) -> 16 | T10: =U10&","&V10 -> bf16,fp4 | U10: bf16 | V10: fp4 | W10: bf16
A11: The dimension of Non-RoPE part of the query head | B11: h_nope | C11: 128 | F11: Total # of chips | G11: =$G$10/$H$18 -> 8 | T11: =U11&","&V11 -> bf16,fp8 | U11: bf16 | V11: fp8 | W11: bf16
A12: The dimension of the RoPE part of the query head | B12: h_rope | C12: 64 | T12: bf16,bf16 | U12: bf16 | V12: bf16 | W12: bf16
A13: The number of Attention Heads (Query) | B13: n_q | C13: 128
A14: [ ↓ Derived parameters]
A15: h_nope+h_rope | B15: h_nope+h_rope | C15: =$C$11+$C$12 -> 192
A16: c_kv+h_rope | B16: c_kv+h_rope | C16: =$C$10+$C$12 -> 576
A17: # of Duplicated tokens (top_k times) | B17: kT | C17: =C8*$C$25 -> 8192 | F17: Hardware Spec | H17: ='Config and Summary'!D4 -> GhostFish (P3) Derated
A18: # of Devices | B18: num_devices | C18: =$G$10 -> 16 | F18: {=DB!A2:A16} -> # of TensorCore per Chip | H18: {=xlookup($H$17,DB!1:1,DB!2:16)} -> 2
A19: # of Chips | B19: num_chips | C19: =$G$11 -> 8 | F19: Per-Chip HBM-BW (GB/s) | H19: 6729.8
A20: [TPU] Assumed Topology | B20: topo | C20: =vlookup(C19, DB!$A$26:$F$31, 5, False) -> 2x2x2 | F20: Per-Chip TFLOPS (fp4) | H20: 3571.236
A21: [TPU] Total # of Bidir Links | B21: num_links_in_topo | C21: =vlookup(C19, DB!$A$26:$F$31, 6, False) -> 12 | F21: Per-Chip TFLOPS (fp8) | H21: 3571.236
F22: Per-Chip TFLOPS (fp16) | H22: 1785.618
A23: [ ↓ Configurable parameters] | F23: Per-Chip HBM Capacity (GiB) | H23: 192
A24: Regime | B24: R | C24: Prefill | F24: Per-Core HBM-BW (GB/s) | H24: 3364.9
A25: Sequence Length (Q) | B25: T | C25: ='Config and Summary'!D14 -> 1024 | F25: Per-Core TFLOPS (fp4) | H25: 1785.618
A26: Batch Size (power of 2) | B26: B | C26: ='Config and Summary'!D15 -> 16 | F26: Per-Core TFLOPS (fp8) | H26: 1785.618
A27: Sequence Length (KV) | B27: S | C27: ='Config and Summary'!D16 -> 1024 | F27: Per-Core TFLOPS (bf16) | H27: 892.809
A28: Scheduler Latency Overhead | C28: ='Config and Summary'!D18 -> 0 | F28: Per-Core HBM Capacity (GiB) | H28: 96
A29: Roofline Discount Rate | C29: ='Config and Summary'!D19 -> 1 | F29: Core-to-Core ICI Bandwidth (uni, GB/s) | H29: 600
A30: Flash Attention Enabled | B30: flash_attn | C30: ='Config and Summary'!D20 -> TRUE | F30: Chip-to-Chip ICI Bandwidth (uni, GB/s) | H30: 80
A31: Enforce Perfect Expert Routing | B31: enforce_perfect_expert_routing | C31: ='Config and Summary'!D21 -> TRUE | F31: Chip-to-Chip ICI Latency (ms) | H31: 0.0013
A32: [ ↓ Configurable Numeric] | F32: Min MXU Contracting Dim | H32: 256
A33: KV Cache dtype | B33: kv_dtype | C33: ='Config and Summary'!D27 -> fp8
A34: Attention Projections Numeric | B34: attn_proj_dtype | C34: ='Config and Summary'!D28 -> w8a8
A35: Attention Output Projection Numerics | B35: attn_oproj_dtype | C35: ='Config and Summary'!D29 -> w8a8
A36: Attention "K" numeric from KV | B36: attn_kv_k_dtype | C36: ='Config and Summary'!D30 -> fp8
A37: Attention "A" numeric from AV | B37: attn_av_a_dtype | C37: ='Config and Summary'!D31 -> fp8
A38: Expert Dispatch Numeric | B38: expert_dispatch_dtype | C38: ='Config and Summary'!D32 -> fp8
A39: MoE Numeric | B39: moe_dtype | C39: ='Config and Summary'!D33 -> w4a8
A40: Expert Collect Numeric | B40: expert_collect_dtype | C40: ='Config and Summary'!D34 -> bf16
...

Sheet Analysis
A2: Config | B2: # Chips | C2: Batch Size | D2: Roofline Decode tps/chip | E2: Roofline Output tps/chip
A3: ='Config and Summary'!C1 -> [1K/8K] GF 2x2x2 DP16/EP16 Aggregated MOE-a8w4 B=2.5K | B3: ='Config and Summary'!C9/'Decode Last Token'!H18 -> 8 | C3: ='Config and Summary'!C15 -> 2560 | D3: ='Config and Summary'!B51 -> 10096.825 | E3: ='Config and Summary'!B59 -> 9359.1659
A6: Summary
B7: Aggregated setup, numerics assumptions are slightly different
B9: Sequence Lengths 1K/8K
A11: System | B11: # Chips | C11: Batch Size | D11: Configuration | E11: Roofline Decode tps/chip | F11: Roofline Output tps/chip | G11: Measured Output tps/chip (April 2026) | H11: % Roofline | I11: % of 4-chip GB200 | J11: % of InferenceX GB200
A12: GF | B12: 4 | C12: 896 | D12: =CONCATENATE(B12, " ", A12, " b",C12) -> 4 GF b896 | E12: 7995.6563 | F12: 7617.1152 | G12: 2760 | H12: =G12/F12 -> 0.3623419 | I12: =G12/$G$13 -> 0.62190176 | J12: =G12/$G$21 -> 0.48789111
A13: GB200 | B13: 4 | C13: 896 | D13: =CONCATENATE(B13, " ", A13, " b",C13) -> 4 GB200 b896 | E13: 8668.2684 | F13: 8275.4296 | G13: 4438 | H13: =G13/F13 -> 0.53628636
A14: GF | B14: 8 | C14: 2560 | D14: =CONCATENATE(B14, " ", A14, " b", C14, " (best)") -> 8 GF b2560 (best) | E14: 10096.825 | F14: 9359.1659 | G14: 2600 | H14: =G14/F14 -> 0.27780253 | I14: =G14/$G$13 -> 0.58584948 | J14: =G14/$G$21 -> 0.45960757
A15: GB200 | B15: 8 | C15: 2560 | D15: =CONCATENATE(B15, " ", A15, " b",C15) -> 8 GB200 b2560 | E15: 12409.605 | F15: 11691.019
A16: GF | B16: 16 | C16: 7168 | D16: =CONCATENATE(B16, " ", A16, " b",C16) -> 16 GF b7168 | E16: 9137.9091 | F16: 8337.1891
A17: GB200 | B17: 16 | C17: 7168 | D17: =CONCATENATE(B17, " ", A17, " b",C17, " (best)") -> 16 GB200 b7168 (best) | E17: 14750.29 | F17: 13746.976
A18: GF | B18: 32 | C18: 12288 | D18: =CONCATENATE(B18, " ", A18, " b",C18) -> 32 GF b12288 | E18: 8468.6125 | F18: 7720.3633
A19: GB200 | B19: 32 | C19: 12288 | D19: =CONCATENATE(B19, " ", A19, " b",C19) -> 32 GB200 b12288 | E19: 13211.79 | F19: 12394.279
A21: GB200 (Disagg InferenceX) | B21: 32+4 | C21: 8192 | D21: =CONCATENATE(B21, " ", A21, " b",C21) -> 32+4 GB200 (Disagg InferenceX) b8192 | E21: 10794.632 | F21: 10319.019 | G21: 5657 | H21: =G21/F21 -> 0.54821104
A23: Plot | K23: Output tps/chip
B24: Roofline Decode tps/chip | J24: Summary | K24: actual | L24: increment
B25: # chips | C25: GFC | D25: GB200 | J25: GF - Mar 2026 (4-chip, best) | K25: 1630
B26: 4 | C26: =E12 -> 7995.6563 | D26: =E13 -> 8668.2684 | J26: GF - May 2026 (4-chip, best) | K26: =G12 -> 2760
B27: 8 | C27: =E14 -> 10096.825 | D27: =E15 -> 12409.605 | J27: GF - June 2026 Projection (4 or 8 chips) | K27: 3427 | L27: =K27*0.2 -> 685.4 | M27: =sum(K27:L27) -> 4112.4
B28: 16 | C28: =E16 -> 9137.9091 | D28: =E17 -> 14750.29 | J28: GB200 4-chip Baseline (Internally produced) | K28: =G13 -> 4438
B29: 32 | C29: =E18 -> 8468.6125 | D29: =E19 -> 13211.79 | J29: GB200 InferenceX 4-chip Baseline | K29: 2073
J30: GB200 InferenceX 32+4 Disagg Baseline | K30: =G21 -> 5657
H37: =14750/9138 -> 1.6141388
H38: =1/H37 -> 0.61952542
H39: =1-H38 -> 0.38047458
B52: # chips | C52: GF Roofline | D52: GF Measured | E52: GB200 Roofline | F52: GB200 Measured/Reported
B53: 4 | C53: =F12 -> 7617.1152 | D53: =G12 -> 2760 | E53: =F13 -> 8275.4296 | F53: =G13 -> 4438
B54: 8 | C54: =F14 -> 9359.1659 | D54: =G14 -> 2600 | E54: =F15 -> 11691.019
B55: 16 | C55: =F16 -> 8337.1891 | E55: =F17 -> 13746.976
B56: 32 | C56: =F18 -> 7720.3633 | E56: =F19 -> 12394.279
B57: 32+4 (Disagg) | E57: =F21 -> 10319.019 | F57: =G21 -> 5657
A92: Breakdown Comparison - Last Decode Token
B94: 8 Chips, Last Decode Token, Single Layer Roofline Operator Comparison
B95: Operator | C95: GFC (ms) | D95: GB200 (ms) | E95: GFC - GB200 (ms) | F95: Contribution to Perf Delta | G95: GB200/GFC time
B96: Q Down Proj | C96: 0.0035 | D96: 0.0038 | E96: =C96-D96 -> -0.0003 | F96: =E96/$C$108 -> -0.00047073592 | G96: =D96/C96 -> 1.0857143
B97: Q Up Proj | C97: 0.0127 | D97: 0.0129 | E97: =C97-D97 -> -0.0002 | F97: =E97/$C$108 -> -0.00031382394 | G97: =D97/C97 -> 1.015748
B98: Q Proj to K | C98: 0.0089 | D98: 0.009 | E98: =C98-D98 -> -0.0001 | F98: =E98/$C$108 -> -0.00015691197 | G98: =D98/C98 -> 1.011236
B99: KV Down Proj | C99: 0.0015 | D99: 0.0017 | E99: =C99-D99 -> -0.0002 | F99: =E99/$C$108 -> -0.00031382394 | G99: =D99/C99 -> 1.1333333
B100: MLA FlashAttention | C100: 0.2706 | D100: 0.2282 | E100: =C100-D100 -> 0.0424 | F100: =E100/$C$108 -> 0.066530676 | G100: =D100/C100 -> 0.84331116
...

Sheet DB
A1: Hardware Spec | C1: GhostFish (P3) | D1: GB200 | E1: GhostFish (P3) Derated | F1: GB200 Derated | H1: GB200 / GFC Derated
A2: # of TensorCore per Chip | C2: 2 | D2: 1 | E2: =$C2 -> 2 | F2: =$D2 -> 1
A3: Per-Chip HBM-BW (GB/s) | C3: 7315 | D3: 8000 | E3: =$C3*E$18 -> 6729.8 | F3: =$D3*F$18 -> 7200 | H3: =F3/E3 -> 1.0698683
A4: Per-Chip TFLOPS (fp4) | C4: =4614*0.86 -> 3968.04 | D4: 10000 | E4: =$C4*E$19 -> 3571.236 | F4: =$D4*F$19 -> 7500 | H4: =F4/E4 -> 2.1001132
A5: Per-Chip TFLOPS (fp8) | C5: =4614*0.86 -> 3968.04 | D5: 5000 | E5: =$C5*E$19 -> 3571.236 | F5: =$D5*F$19 -> 3750 | H5: =F5/E5 -> 1.0500566
A6: Per-Chip TFLOPS (fp16) | C6: =2307*0.86 -> 1984.02 | D6: 2500 | E6: =$C6*E$19 -> 1785.618 | F6: =$D6*F$19 -> 1875 | H6: =F6/E6 -> 1.0500566
A7: Per-Chip HBM Capacity (GiB) | C7: 192 | D7: =round(192*1000000000/(1024^3), 0) -> 179 | E7: =$C7 -> 192 | F7: =$D7 -> 179 | H7: =F7/E7 -> 0.93229167
A8: Per-Core HBM-BW (GB/s) | C8: =C3/C$2 -> 3657.5 | D8: =D3/D$2 -> 8000 | E8: =$C8*E$18 -> 3364.9 | F8: =$D8*F$18 -> 7200
A9: Per-Core TFLOPS (fp4) | C9: =C4/C$2 -> 1984.02 | D9: =D4/D$2 -> 10000 | E9: =$C9*E$19 -> 1785.618 | F9: =$D9*F$19 -> 7500
A10: Per-Core TFLOPS (fp8) | C10: =C5/C$2 -> 1984.02 | D10: =D5/D$2 -> 5000 | E10: =$C10*E$19 -> 1785.618 | F10: =$D10*F$19 -> 3750
A11: Per-Core TFLOPS (bf16) | C11: =C6/C$2 -> 992.01 | D11: =D6/D$2 -> 2500 | E11: =$C11*E$19 -> 892.809 | F11: =$D11*F$19 -> 1875
A12: Per-Core HBM Capacity (GiB) | C12: =C7/$C$2 -> 96 | D12: =D7/D$2 -> 179 | E12: =$C12 -> 96 | F12: =$D12 -> 179
A13: Core-to-Core ICI Bandwidth (uni, GB/s) | C13: 1600 | D13: 900 | E13: =$C13*E$20 -> 600 | F13: =$D13*F$20 -> 900
A14: Chip-to-Chip ICI Bandwidth (uni, GB/s) | C14: 100 | D14: 900 | E14: =$C14*E$21 -> 80 | F14: =$D14*F$21 -> 900
A15: Chip-to-Chip ICI Latency (ms) | C15: 0.0013 | D15: 0 | E15: =$C15 -> 0.0013 | F15: =$D15 -> 0
A16: Min MXU Contracting Dim | C16: 256 | D16: 1 | E16: =$C16 -> 256 | F16: =$D16 -> 1
A18: HBM BW Derate | E18: 0.92 | F18: 0.9
A19: TFLOPS Derate | E19: 0.9 | F19: 0.75
A20: Core-to-Core Interconnect Derate | E20: 0.375 | F20: 1
A21: Chip-to-Chip Interconnect Derate | E21: 0.8 | F21: 1
A25: GFC Topology and Bandwidth Table
A26: # Chips | B26: Detailed Topology (m=mesh, t=torus) | C26: # of Bisection Links (bidirectional) | D26: Total # Unidirectional Links | E26: Simplified Topology | F26: Total # Bidirectional Links | G26: Max # Hops
A27: 2 | B27: 2m | C27: 1 | D27: 2 | E27: 2 | F27: =D27/2 -> 1 | G27: 1
A28: 4 | B28: 2m,2m | C28: 2 | D28: 8 | E28: 2x2 | F28: =D28/2 -> 4 | G28: 2
A29: 8 | B29: 2m,2m,2m | C29: 4 | D29: 24 | E29: 2x2x2 | F29: =D29/2 -> 12 | G29: 3
A30: 16 | B30: 4t,4t | C30: 8 | D30: 64 | E30: 4x4 | F30: =D30/2 -> 32 | G30: =2+2 -> 4
A31: 32 | B31: 4t,4t,2m | C31: 16 | D31: =80*2 -> 160 | E31: 4x4x2 | F31: =D31/2 -> 80 | G31: 5

Sheet NCCL Benchmark
A1: chip | B1: operation | C1: size | D1: num_chips | E1: time | F1: algbw | G1: busbw | H1: datetime | I1: AG/RS/A2A theoretical time GB200 (us) | J1: % of theoretical
A2: B200 | B2: all_gather | C2: 128 | D2: 2 | E2: 8.52 | F2: 0.02 | G2: 0.01 | H2: 45960.839
A3: B200 | B3: all_gather | C3: 256 | D3: 2 | E3: 8.58 | F3: 0.03 | G3: 0.01 | H3: 45960.839
A4: B200 | B4: all_gather | C4: 512 | D4: 2 | E4: 8.66 | F4: 0.06 | G4: 0.03 | H4: 45960.839
A5: B200 | B5: all_gather | C5: 1024 | D5: 2 | E5: 8.68 | F5: 0.12 | G5: 0.06 | H5: 45960.839
A6: B200 | B6: all_gather | C6: 2048 | D6: 2 | E6: 8.77 | F6: 0.23 | G6: 0.12 | H6: 45960.839
A7: B200 | B7: all_gather | C7: 4096 | D7: 2 | E7: 8.95 | F7: 0.46 | G7: 0.23 | H7: 45960.839
A8: B200 | B8: all_gather | C8: 8192 | D8: 2 | E8: 9.4 | F8: 0.87 | G8: 0.44 | H8: 45960.839
A9: B200 | B9: all_gather | C9: 16384 | D9: 2 | E9: 9.62 | F9: 1.7 | G9: 0.85 | H9: 45960.839
A10: B200 | B10: all_gather | C10: 32768 | D10: 2 | E10: 9.81 | F10: 3.34 | G10: 1.67 | H10: 45960.839
A11: B200 | B11: all_gather | C11: 65536 | D11: 2 | E11: 10.04 | F11: 6.53 | G11: 3.26 | H11: 45960.839
A12: B200 | B12: all_gather | C12: 131072 | D12: 2 | E12: 10.06 | F12: 13.03 | G12: 6.51 | H12: 45960.839
A13: B200 | B13: all_gather | C13: 262144 | D13: 2 | E13: 10.19 | F13: 25.72 | G13: 12.86 | H13: 45960.839
... A705: B200 | B705: reduce_scatter | C705: 4294967296 | D705: 8 | E705: 5710.9 | F705: 752.07 | G705: 658.06 | H705: 45960.839
A706: GB200 | B706: ALL_GATHER | C706: 128 | D706: 2 | E706: 10.29 | F706: 0.01 | G706: 0.01 | H706: 46096 | I706: =(D706-1)*(C706/D706)/(900*1000*1000*1000)*1000*1000 -> 7.1111111e-05 | J706: =I706/E706 -> 6.9107008e-06
A707: GB200 | B707: ALL_GATHER | C707: 256 | D707: 2 | E707: 10.14 | F707: 0.03 | G707: 0.01 | H707: 46096 | I707: =(D707-1)*(C707/D707)/(900*1000*1000*1000)*1000*1000 -> 0.00014222222 | J707: =I707/E707 -> 1.402586e-05
A708: GB200 | B708: ALL_GATHER | C708: 512 | D708: 2 | E708: 10.22 | F708: 0.05 | G708: 0.03 | H708: 46096 | I708: =(D708-1)*(C708/D708)/(900*1000*1000*1000)*1000*1000 -> 0.00028444444 | J708: =I708/E708 -> 2.7832137e-05
A709: GB200 | B709: ALL_GATHER | C709: 1024 | D709: 2 | E709: 10.26 | F709: 0.1 | G709: 0.05 | H709: 46096 | I709: =(D709-1)*(C709/D709)/(900*1000*1000*1000)*1000*1000 -> 0.00056888889 | J709: =I709/E709 -> 5.544726e-05
A710: GB200 | B710: ALL_GATHER | C710: 2048 | D710: 2 | E710: 10.34 | F710: 0.2 | G710: 0.1 | H710: 46096 | I710: =(D710-1)*(C710/D710)/(900*1000*1000*1000)*1000*1000 -> 0.0011377778 | J710: =I710/E710 -> 0.00011003654
A711: GB200 | B711: ALL_GATHER | C711: 4096 | D711: 2 | E711: 10.78 | F711: 0.38 | G711: 0.19 | H711: 46096 | I711: =(D711-1)*(C711/D711)/(900*1000*1000*1000)*1000*1000 -> 0.0022755556 | J711: =I711/E711 -> 0.0002110905
A712: GB200 | B712: ALL_GATHER | C712: 8192 | D712: 2 | E712: 10.8 | F712: 0.76 | G712: 0.38 | H712: 46096 | I712: =(D712-1)*(C712/D712)/(900*1000*1000*1000)*1000*1000 -> 0.0045511111 | J712: =I712/E712 -> 0.00042139918
A713: GB200 | B713: ALL_GATHER | C713: 16384 | D713: 2 | E713: 10.89 | F713: 1.5 | G713: 0.75 | H713: 46096 | I713: =(D713-1)*(C713/D713)/(900*1000*1000*1000)*1000*1000 -> 0.0091022222 | J713: =I713/E713 -> 0.00083583308
A714: GB200 | B714: ALL_GATHER | C714: 32768 | D714: 2 | E714: 10.95 | F714: 2.99 | G714: 1.5 | H714: 46096 | I714: =(D714-1)*(C714/D714)/(900*1000*1000*1000)*1000*1000 -> 0.018204444 | J714: =I714/E714 -> 0.0016625063
A715: GB200 | B715: ALL_GATHER | C715: 65536 | D715: 2 | E715: 11.18 | F715: 5.86 | G715: 2.93 | H715: 46096 | I715: =(D715-1)*(C715/D715)/(900*1000*1000*1000)*1000*1000 -> 0.036408889 | J715: =I715/E715 -> 0.003256609
A716: GB200 | B716: ALL_GATHER | C716: 131072 | D716: 2 | E716: 11.15 | F716: 11.76 | G716: 5.88 | H716: 46096 | I716: =(D716-1)*(C716/D716)/(900*1000*1000*1000)*1000*1000 -> 0.072817778 | J716: =I716/E716 -> 0.0065307424
A717: GB200 | B717: ALL_GATHER | C717: 262144 | D717: 2 | E717: 11.68 | F717: 22.44 | G717: 11.22 | H717: 46096 | I717: =(D717-1)*(C717/D717)/(900*1000*1000*1000)*1000*1000 -> 0.14563556 | J717: =I717/E717 -> 0.012468798
... A2334: GB200 | B2334: REDUCE_SCATTER | C2334: 17179869184 | D2334: 32 | E2334: 23795.2 | F2334: 721.99 | G2334: 699.43 | H2334: 46096 | I2334: =(D2334-1)*(C2334/D2334)/(900*1000*1000*1000)*1000*1000 -> 18492.22 | J2334: =I2334/E2334 -> 0.77714078

Sheet Ming test Decode Last Token
A1: Contact: donghyun@, gpolovets@, miliu@. Feedback/Bug reports are welcome!
A2: Description | B2: Symbol | C2: Value | F2: Sharding (Axis Name) | G2: # of Devices | H2: Notes | Q2: Size In Bytes | T2: MXU dtype
A3: Embedding Dimension | B3: D | C3: 7168 | F3: [ ↓ Configurable Values] | Q3: fp4 | R3: 0.5 | T3: =U3&","&V3 -> fp4,fp4 | U3: fp4 | V3: fp4 | W3: fp4
A4: Hidden Dimension | B4: F | C4: 2048 | F4: model | G4: ='Config and Summary'!$C8 -> 1 | Q4: fp8 | R4: 1 | T4: =U4&","&V4 -> fp4,fp8 | U4: fp4 | V4: fp8 | W4: fp8
A5: # of experts | B5: E | C5: 256 | F5: data | G5: ='Config and Summary'!$C9 -> 16 | H5: Also used for expert sharding for MoE | Q5: bf16 | R5: 2 | T5: =U5&","&V5 -> fp4,bf16 | U5: fp4 | V5: bf16 | W5: bf16
A6: # of Layers | B6: L | C6: 61 | F6: seq | G6: ='Config and Summary'!$C10 -> 1 | T6: =U6&","&V6 -> fp8,fp4 | U6: fp8 | V6: fp4 | W6: fp8
A7: # of Dense Layers | B7: DL | C7: 3 | F7: attn_model | G7: ='Config and Summary'!$C11 -> 1 | H7: Used if attention is replicated | T7: =U7&","&V7 -> fp8,fp8 | U7: fp8 | V7: fp8 | W7: fp8
A8: # of experts to be activated per token | B8: top_k | C8: 8 | F8: [ ↓ Derived Values]
A9: The dimension of the compressed latent vector for Query | B9: c_q | C9: 1536 | F9: data,model | G9: =G5*G4 -> 16 | T9: =U9&","&V9 -> fp8,bf16 | U9: fp8 | V9: bf16 | W9: bf16
A10: The dimension of the compressed latent vector for KV | B10: c_kv | C10: 512 | F10: Total # of devices | G10: =PRODUCT(G3:G6) -> 16 | T10: =U10&","&V10 -> bf16,fp4 | U10: bf16 | V10: fp4 | W10: bf16
A11: The dimension of Non-RoPE part of the query head | B11: h_nope | C11: 128 | F11: Total # of chips | G11: =$G$10/$H$18 -> 8 | T11: =U11&","&V11 -> bf16,fp8 | U11: bf16 | V11: fp8 | W11: bf16
A12: The dimension of the RoPE part of the query head | B12: h_rope | C12: 64 | T12: bf16,bf16 | U12: bf16 | V12: bf16 | W12: bf16
A13: The number of Attention Heads (Query) | B13: n_q | C13: 128
A14: [ ↓ Derived parameters]
A15: h_nope+h_rope | B15: h_nope+h_rope | C15: =$C$11+$C$12 -> 192
A16: c_kv+h_rope | B16: c_kv+h_rope | C16: =$C$10+$C$12 -> 576
A17: # of Duplicated tokens (top_k times) | B17: kT | C17: =C8*$C$25 -> 8 | F17: Hardware Spec | H17: ='Config and Summary'!C4 -> GhostFish (P3) Derated
A18: # of Devices | B18: num_devices | C18: =$G$10 -> 16 | F18: {=DB!A2:A16} -> # of TensorCore per Chip | H18: {=xlookup($H$17,DB!1:1,DB!2:16)} -> 2
A19: # of Chips | B19: num_chips | C19: =$G$11 -> 8 | F19: Per-Chip HBM-BW (GB/s) | H19: 6729.8
A20: [TPU] Assumed Topology | B20: topo | C20: =vlookup(C19, DB!$A$26:$F$31, 5, False) -> 2x2x2 | F20: Per-Chip TFLOPS (fp4) | H20: 3571.236
A21: [TPU] Total # of Bidir Links | B21: num_links_in_topo | C21: =vlookup(C19, DB!$A$26:$F$31, 6, False) -> 12 | F21: Per-Chip TFLOPS (fp8) | H21: 3571.236
F22: Per-Chip TFLOPS (fp16) | H22: 1785.618
A23: [ ↓ Configurable parameters] | F23: Per-Chip HBM Capacity (GiB) | H23: 192
A24: Regime | B24: R | C24: Decode | F24: Per-Core HBM-BW (GB/s) | H24: 3364.9
A25: Sequence Length (Q) | B25: T | C25: ='Config and Summary'!C14 -> 1 | F25: Per-Core TFLOPS (fp4) | H25: 1785.618
A26: Batch Size (power of 2) | B26: B | C26: ='Config and Summary'!C15 -> 2560 | F26: Per-Core TFLOPS (fp8) | H26: 1785.618
A27: Sequence Length (KV) | B27: S | C27: ='Config and Summary'!C16 -> 9216 | F27: Per-Core TFLOPS (bf16) | H27: 892.809
A28: Scheduler Latency Overhead | C28: ='Config and Summary'!C18 -> 0 | F28: Per-Core HBM Capacity (GiB) | H28: 96
A29: Roofline Discount Rate | C29: ='Config and Summary'!C19 -> 1 | F29: Core-to-Core ICI Bandwidth (uni, GB/s) | H29: 600
A30: Flash Attention Enabled | B30: flash_attn | C30: ='Config and Summary'!C20 -> TRUE | F30: Chip-to-Chip ICI Bandwidth (uni, GB/s) | H30: 80
A31: Enforce Perfect Expert Routing | B31: enforce_perfect_expert_routing | C31: ='Config and Summary'!C21 -> TRUE | F31: Chip-to-Chip ICI Latency (ms) | H31: 0.0013
A32: [ ↓ Configurable Numeric] | F32: Min MXU Contracting Dim | H32: 256
A33: KV Cache dtype | B33: kv_dtype | C33: ='Config and Summary'!C27 -> fp8
A34: Attention Projections Numeric | B34: attn_proj_dtype | C34: ='Config and Summary'!C28 -> w8a8
A35: Attention Output Projection Numerics | B35: attn_oproj_dtype | C35: ='Config and Summary'!C29 -> w8a8
A36: Attention "K" numeric from KV | B36: attn_kv_k_dtype | C36: ='Config and Summary'!C30 -> fp8
A37: Attention "A" numeric from AV | B37: attn_av_a_dtype | C37: ='Config and Summary'!C31 -> fp8
A38: Expert Dispatch Numeric | B38: expert_dispatch_dtype | C38: ='Config and Summary'!C32 -> fp8
A39: MoE Numeric | B39: moe_dtype | C39: ='Config and Summary'!C33 -> w4a8
A40: Expert Collect Numeric | B40: expert_collect_dtype | C40: ='Config and Summary'!C34 -> bf16
...

Sheet Weight Absorb Analysis
A3: Tensor | B3: Dimensions | E3: dtype bytes | F3: Size (MiB)
A4: Wo | B4: n_q | C4: h_nope | D4: D
B5: 128 | C5: 128 | D5: 7168 | E5: 1 | F5: =product(B5:E5)/1024/1024 -> 112
A6: Wuv | B6: n_q | C6: h_nope | D6: c_kv
B7: 128 | C7: 128 | D7: 512 | E7: 1 | F7: =product(B7:E7)/1024/1024 -> 8
E8: Total | F8: =F5+F7 -> 120
A10: Wuv*Wo (contract on h_nope) | B10: n_q | C10: c_kv | D10: D
B11: 128 | C11: 512 | D11: 7168 | E11: 1 | F11: =product(B11:E11)/1024/1024 -> 448
A12: Activation Saved (if not already in VMEM) | B12: B | C12: n_q | D12: h_nope
B13: 256 | C13: 128 | D13: 192 | E13: 2 | F13: =product(B13:E13)/1024/1024 -> 12
E14: Total | F14: =F11-F13 -> 436
A16: Wuk | B16: n_q | C16: h_nope | D16: c_kv
B17: 128 | C17: 128 | D17: 512 | E17: 1 | F17: =product(B17:E17)/1024/1024 -> 8
A18: Wuq | B18: c_q | C18: n_q | D18: h_nope
B19: 1536 | C19: 128 | D19: 128 | E19: 1 | F19: =product(B19:E19)/1024/1024 -> 24
E20: Total | F20: =F17+F19 -> 32
A22: Wuq*Wuk' (contract on h_nope) | B22: n_q | C22: c_q | D22: c_kv
B23: 128 | C23: 1536 | D23: 512 | E23: 1 | F23: =product(B23:E23)/1024/1024 -> 96
A24: Activation Saved (if not already in VMEM) | B24: B | C24: n_q | D24: h_nope
B25: 256 | C25: 128 | D25: 128 | E25: 2 | F25: =product(B25:E25)/1024/1024 -> 8
E26: Total | F26: =F23-F25 -> 88

Sheet Token Time Linear Interpolation
B1: Config: | C1: [1K/8K] GF 2x2 DP8/EP8 Aggregated MOE-a8w4
B2: Check modled roofline time vs linearly interpolated roofline time based on first / last token
B3: Seems close enough: | F3: 61
B4: KV len | C4: Time all layers (s) - Roofline | D4: Time all layers if linearly interpolated (s) | E4: delta | F4: Measured (all layers) | G4: % roofline
B5: 1024 | C5: 0.0241 | D5: =$C$5 + (($C$13 - $C$5) / ($B$13 - $B$5)) * (B5 - $B$5) -> 0.0241 | E5: =C5/D5-1 -> 0 | F5: =1.039*61/1000 -> 0.063379 | G5: =C5/F5 -> 0.38025213
B6: =B5+1024 -> 2048 | C6: 0.0254 | D6: =$C$5 + (($C$13 - $C$5) / ($B$13 - $B$5)) * (B6 - $B$5) -> 0.0255375 | E6: =C6/D6-1 -> -0.0053842389
B7: =B6+1024 -> 3072 | C7: 0.0268 | D7: =$C$5 + (($C$13 - $C$5) / ($B$13 - $B$5)) * (B7 - $B$5) -> 0.026975 | E7: =C7/D7-1 -> -0.0064874884
B8: =B7+1024 -> 4096 | C8: 0.0283 | D8: =$C$5 + (($C$13 - $C$5) / ($B$13 - $B$5)) * (B8 - $B$5) -> 0.0284125 | E8: =C8/D8-1 -> -0.0039595249 | F8: =1.2*$F$3/1000 -> 0.0732 | G8: =C8/F8 -> 0.38661202
B9: =B8+1024 -> 5120 | C9: 0.0297 | D9: =$C$5 + (($C$13 - $C$5) / ($B$13 - $B$5)) * (B9 - $B$5) -> 0.02985 | E9: =C9/D9-1 -> -0.0050251256
B10: =B9+1024 -> 6144 | C10: 0.0312 | D10: =$C$5 + (($C$13 - $C$5) / ($B$13 - $B$5)) * (B10 - $B$5) -> 0.0312875 | E10: =C10/D10-1 -> -0.002796644
B11: =B10+1024 -> 7168 | C11: 0.0327 | D11: =$C$5 + (($C$13 - $C$5) / ($B$13 - $B$5)) * (B11 - $B$5) -> 0.032725 | E11: =C11/D11-1 -> -0.00076394194
B12: =B11+1024 -> 8192 | C12: 0.0341 | D12: =$C$5 + (($C$13 - $C$5) / ($B$13 - $B$5)) * (B12 - $B$5) -> 0.0341625 | E12: =C12/D12-1 -> -0.0018294914
B13: =B12+1024 -> 9216 | C13: 0.0356 | D13: =$C$5 + (($C$13 - $C$5) / ($B$13 - $B$5)) * (B13 - $B$5) -> 0.0356 | E13: =C13/D13-1 -> 0 | F13: =1.488*F3/1000 -> 0.090768 | G13: =C13/F13 -> 0.39220871

Sheet DEPRECATED FROM HERE ON -->

Sheet Roofline Worksheet
A1: Contact: donghyun@, gpolovets@, miliu@. Feedback/Bug reports are welcome!
A2: Description | B2: Symbol | C2: Value | F2: Sharding (Axis Name) | G2: # of Devices | H2: Notes | Q2: Size In Bytes | T2: MXU dtype
A3: Embedding Dimension | B3: D | C3: 7168 | F3: [ ↓ Configurable Values] | Q3: fp4 | R3: 0.5 | T3: =U3&","&V3 -> fp4,fp4 | U3: fp4 | V3: fp4 | W3: fp4
A4: Hidden Dimension | B4: F | C4: 2048 | F4: model | G4: 1 | Q4: fp8 | R4: 1 | T4: =U4&","&V4 -> fp4,fp8 | U4: fp4 | V4: fp8 | W4: fp8
A5: # of experts | B5: E | C5: 256 | F5: data | G5: 16 | H5: Also used for expert sharding for MoE | Q5: bf16 | R5: 2 | T5: =U5&","&V5 -> fp4,bf16 | U5: fp4 | V5: bf16 | W5: bf16
A6: # of Layers | B6: L | C6: 61 | F6: seq | G6: 1 | T6: =U6&","&V6 -> fp8,fp4 | U6: fp8 | V6: fp4 | W6: fp8
A7: # of Dense Layers | B7: DL | C7: 3 | F7: attn_model | G7: 1 | H7: Used if attention is replicated | T7: =U7&","&V7 -> fp8,fp8 | U7: fp8 | V7: fp8 | W7: fp8
A8: # of experts to be activated per token | B8: top_k | C8: 8 | F8: [ ↓ Derived Values]
A9: The dimension of the compressed latent vector for Query | B9: c_q | C9: 1536 | F9: data,model | G9: =G5*G4 -> 16 | T9: =U9&","&V9 -> fp8,bf16 | U9: fp8 | V9: bf16 | W9: bf16
A10: The dimension of the compressed latent vector for KV | B10: c_kv | C10: 512 | F10: Total # of devices | G10: =PRODUCT(G3:G6) -> 16 | T10: =U10&","&V10 -> bf16,fp4 | U10: bf16 | V10: fp4 | W10: bf16
A11: The dimension of Non-RoPE part of the query head | B11: h_nope | C11: 128 | F11: Total # of chips | G11: =$G$10/$H$18 -> 8 | T11: =U11&","&V11 -> bf16,fp8 | U11: bf16 | V11: fp8 | W11: bf16
A12: The dimension of the RoPE part of the query head | B12: h_rope | C12: 64 | L12: TODO LIST | T12: bf16,bf16 | U12: bf16 | V12: bf16 | W12: bf16
A13: The number of Attention Heads (Query) | B13: n_q | C13: 128
A14: [ ↓ Derived parameters]
A15: h_nope+h_rope | B15: h_nope+h_rope | C15: =$C$11+$C$12 -> 192
A16: c_kv+h_rope | B16: c_kv+h_rope | C16: =$C$10+$C$12 -> 576
A17: # of Duplicated tokens (top_k times) | B17: kT | C17: =C8*$C$24 -> 8 | F17: Hardware Spec | G17: Derate Factor | H17: GhostFish (P3)
A18: # of Devices | B18: num_devices | C18: =$G$10 -> 16 | F18: {=DB!A2:A16} -> # of TensorCore per Chip | G18: 1 | H18: {=xlookup($H$17,DB!1:1,DB!2:16) * G18:G32} -> 2
A19: # of Chips | B19: num_chips | C19: =$G$11 -> 8 | F19: Per-Chip HBM-BW (GB/s) | G19: 0.8 | H19: 5852
A20: Assumed Topology | B20: topo | C20: =IFS(C19=16,"2x2x4",C19=8,"2x2x2",C19=4,"2x2",TRUE,NA) -> 2x2x2 | F20: Per-Chip TFLOPS (fp4) | G20: 1 | H20: 3968.04
A21: # of Links in the current topology | B21: num_links_in_topo | C21: =IFS(C20="2x2x4",32,C20="2x2x2",12,C20="2x2",4,TRUE,NA()) -> 12 | F21: Per-Chip TFLOPS (fp8) | G21: 1 | H21: 3968.04
A22: [ ↓ Configurable parameters] | F22: Per-Chip TFLOPS (fp16) | G22: 1 | H22: 1984.02
A23: Regime | B23: R | C23: Decode | F23: Per-Chip HBM Capacity (GiB) | G23: 1 | H23: 192
A24: Sequence Length (Q) | B24: T | C24: =IF(C23="Decode", 1, 2048) -> 1 | F24: Per-Core HBM-BW (GB/s) | G24: 0.8 | H24: 2926
A25: Batch Size (power of 2) | B25: B | C25: 2048 | F25: Per-Core TFLOPS (fp4) | G25: 1 | H25: 1984.02
A26: Sequence Length (KV) | B26: S | C26: =1024+4096 -> 5120 | F26: Per-Core TFLOPS (fp8) | G26: 1 | H26: 1984.02
A27: Scheduler Latency Overhead | C27: 0 | F27: Per-Core TFLOPS (bf16) | G27: 1 | H27: 992.01
A28: Roofline Discount Rate | C28: 1 | F28: Per-Core HBM Capacity (GiB) | G28: 1 | H28: 96
A29: Flash Attention Enabled | B29: flash_attn | C29: TRUE | F29: Core-to-Core ICI Bandwidth (uni, GB/s) | G29: 0.375 | H29: 600
A30: Enforce Perfect Expert Routing | B30: enforce_perfect_expert_routing | C30: TRUE | F30: Chip-to-Chip ICI Bandwidth (uni, GB/s) | G30: 0.8 | H30: 80
A31: Expert Imbalance Ratio | B31: expert_imbalance_ratio | C31: 1 | F31: Chip-to-Chip ICI Latency (ms) | G31: 1 | H31: 0.0013
A32: [ ↓ Configurable Numeric] | F32: Min MXU Contracting Dim | G32: 1 | H32: 256
A33: KV Cache dtype | B33: kv_dtype | C33: fp8
A34: Attention Projections Numeric | B34: attn_proj_dtype | C34: w8a8 | F34: Maximum Batchsize Calculation
A35: Attention "K" numeric from QK | B35: attn_kv_k_dtype | C35: fp8 | F35: Model Weights Dtype | G35: fp8
A36: Attention "A" numeric from AV | B36: attn_av_a_dtype | C36: bf16 | F36: KV Cache Dtype | G36: =C33 -> fp8
A37: Expert Dispatch Numeric | B37: expert_dispatch_dtype | C37: fp8 | F37: Shared Expert Strategy | G37: Strategy A: All-Gather Tokens
A38: MoE Numeric | B38: moe_dtype | C38: w4a8
A39: Expert Collect Numeric | B39: expert_collect_dtype | C39: bf16 | F39: # of Model Params | G39: =671*1000000000 -> 671000000000
F40: # of Attention Params | G40: =SUM(PRODUCT(L87:M87), PRODUCT(K144:M144), PRODUCT(K171:M171), PRODUCT(L190:M190), PRODUCT(K296:M296), PRODUCT(K330:M330)) * PARAMS("L") -> 11413422080
...

Sheet Sharding Eq
A2: ds + fs sharding
A3: Operator | B3: LHS | C3: RHS | D3: Output | E3: Collectives | F3: Comment
B4: [B|fs|ds, t=1, D] | F4: output of attention (replicated)
B5: [B|fs|ds, t=1, D] | D5: [B, t=1, D|ds] | E5: AG on fs and ds + slice or RA2A exchange
A6: Dispatch | B6: [B, t=1, D|ds] | D6: [E, K, C, D|ds] | F6: after dispatch, where K = topK and C = B / #experts = tokens/expert (assuming even distribution)
A7: FFi / FFiG | B7: [E, K, C, D|ds] | C7: [E, 2, D|ds, F|fs] | D7: [E, K, C, 2, F|fs|ds] | E7: Output: RS along ds
A8: Activation / VPU | B8: [E, K, C, 2, F|fs|ds] | D8: [E, K, C, F|fs|ds]
A9: FFo | B9: [E, K, C, F|fs] | C9: [E, D|ds, F|fs] | D9: [E, K, C|fs, D|ds] | E9: Input: AG along ds Output: RS along fs
A10: Collect | B10: [E, K, C|fs, D|ds] | D10: [B|fs, t=1, D|ds] | F10: collect, summed across activated experts
B11: [B|fs, t=1, D|ds] | D11: [B|fs|ds, t=1, D] | E11: AG along ds + slice
A13: es sharding
A14: Operator | B14: LHS | C14: RHS | D14: Output | E14: Collectives | F14: Comment
B15: [B|es, t=1, D] | F15: output of attention (replicated)
A16: Dispatch | B16: [B|es, t=1, D] | D16: [E|es, K, C, D] | E16: RA2A along es or AG along es + slice | F16: after dispatch, where K = topK and C = B / #experts = tokens/expert (assuming even distribution) If we do AG, we expand tokens (topk times) after the collective. If we do A2A, we expand tokens before the collectives.
A17: FFi / FFiG | B17: [E|es, K, C, D] | C17: [E|es, 2, D, F] | D17: [E|es, K, C, 2, F]
A18: Activation / VPU | B18: [E|es, K, C, 2, F] | D18: [E|es, K, C, F]
A19: FFo | B19: [E|es, K, C, F] | C19: [E|es, D, F] | D19: [E|es, K, C, D]
A20: Collect | B20: [E|es, K, C, D] | D20: [B|es, t=1, D] | E20: transpose RA2A along es or pad + RS along es | F20: collect, summed across activated experts In RS path, we'll need to unsort tokens (expert-sorted to sequence-sorted) and pad before RS
A25: Experimentation
A26: ds + fs sharding
A27: Operator | B27: LHS | C27: RHS | D27: Output | E27: Collectives | F27: Comment
B28: [B|fs|ds, t=1, D] | F28: output of attention (replicated)
B29: [B|fs|ds, t=1, D] | D29: [B, t=1, D|ds] | E29: AG on fs and ds + slice or RA2A exchange
A30: Dispatch | B30: [B, t=1, D|ds] | D30: [E, K, C, D|ds] | F30: after dispatch, where K = topK and C = B / #experts = tokens/expert (assuming even distribution)
A31: FFi / FFiG | B31: [E, C, D|ds] | C31: [E, 2, D|ds, F|fs] | D31: [E, C, 2, F|fs|ds] | E31: Output: RS along ds
